Workbook

Sheet Summary
A1: A4: Dark-store break-even model (Swiggy Instamart, Q1 FY27)
A2: One-page recommendation. Every number below is a live formula. Disclosed inputs: Swiggy Q1 FY27 letter and KPI databook; Blinkit benchmark: Eternal Q1 FY27.
A4: Business question
A5: How many orders a day, at what AOV, does a dark store need to move from Instamart's -0.2% contribution margin to +2%, and which lever (AOV, delivery fee, ad income, discounts, rider cost) gets there cheapest?
A7: Headline | B7: Value | D7: Note
A8: Orders per store per day today | B8: =Model!B21 -> 1074.5019 | D8: Rebuilt from disclosed orders, stores and days.
A9: Break-even orders per store per day | B9: =Model!B31 -> 1132.9282 | D9: Where contribution after fixed cost is zero, at today's AOV and cost structure.
A10: Increase needed vs today | B10: =Model!B32 -> 0.054375197
A11: Orders per store per day for the target margin | B11: =Model!B33 -> 2483.141 | D11: Volume alone is a very long way off the target.
A12: Contribution per order today (₹) | B12: =Model!B25 -> -1.382 | D12: -0.2% of AOV.
A13: Contribution per store per month today (₹) | B13: =Model!B28 -> -44548.85
A14: Fixed cost per store per month, calibrated (₹) | B14: =Model!B23 -> 863835.08 | D14: Not disclosed. Solved from the disclosed total cost per order and my variable-cost assumptions.
A15: Effect of a +10% AOV lift: contribution per store per month (₹) | B15: =INDEX(Tornado!H6:H16,MATCH("AOV",Tornado!A6:A16,0)) -> 243103.91 | D15: ="₹"&TEXT(B15*3*Inputs!B11/10000000,"0.0")&" crore a quarter across "&TEXT(Inputs!B11,"#,##0")&" stores, volume held constant" -> ₹85.4 crore a quarter across 1,171 stores, volume held constant
A16: Top two levers by swing (move each input ±10%, others at base)
A17: Lever | B17: Swing, ₹ per store per month | C17: Swing, all stores, ₹ crore a month | D17: Reading
A18: =Tornado!A6 -> AOV | B18: =Tornado!I6 -> 486207.82 | C18: =Tornado!J6 -> 56.934936 | D18: A 10% move either way. Inputs move alone; real changes interact.
A19: =Tornado!A7 -> Rider cost per order | B19: =Tornado!I7 -> 290115.52 | C19: =Tornado!J7 -> 33.972527 | D19: A 10% move either way. Inputs move alone; real changes interact.
A21: Recommendation
A22: ="1. Hold today's volume and push the two biggest levers above: "&A18&" and "&A19&". Break-even needs "&TEXT(Model!B31,"#,##0")&" orders per store per day, "&TEXT(Model!B32,"0.0%")&" above today's "&TEXT(Model!B21,"#,##0")&"." -> 1. Hold today's volume and push the two biggest levers above: AOV and Rider cost per order. Break-even needs 1,133 orders per store per day, 5.4% above today's 1,075.
A23: ="2. Volume alone will not deliver a +"&TEXT(Inputs!B49,"0%")&" margin: it needs about "&TEXT(Model!B33,"#,##0")&" orders per store per day ("&TEXT(Model!B34,"0%")&" above today). Basket value, fees and ad income must carry the rest." -> 2. Volume alone will not deliver a +2% margin: it needs about 2,483 orders per store per day (131% above today). Basket value, fees and ad income must carry the rest.
A24: ="3. A ₹"&TEXT(Scenarios!E5,"0")&" higher AOV with small ad, fee and rider gains (the lever pack) adds ₹"&TEXT(Scenarios!E29,"#,##0")&" contribution per store per month (₹"&TEXT(Scenarios!E29*Inputs!B11/10000000,"0.0")&" crore a month across "&TEXT(Inputs!B11,"#,##0")&" stores)." -> 3. A ₹60 higher AOV with small ad, fee and rider gains (the lever pack) adds ₹565,674 contribution per store per month (₹66.2 crore a month across 1,171 stores).
A25: ="4. A discount war does the opposite: it changes contribution per store per month by "&TEXT(Scenarios!D29,"₹#,##0;-₹#,##0")&", even with "&TEXT(Scenarios!D6,"0%")&" more orders." -> 4. A discount war does the opposite: it changes contribution per store per month by -₹272,657, even with 10% more orders.
A27: Limits to say out loud
A28: • Public data gives total cost per order but not its split. Rider, picking, packaging, payment, wastage, fee, ad income and discount per order are my assumptions (yellow cells on Inputs).
A29: • Fixed cost is solved so the model reproduces the disclosed -0.2% contribution; it is then cross-checked against a rent, staff and power guess on the Model sheet.
A30: • Levers move one at a time. Real levers interact: more discount lifts orders but cuts AOV and margin.
A31: • Q1 FY27 is one quarter of Instamart as a whole. Individual stores differ widely in density, rent and AOV.
A32: • Checks sheet confirms the model reproduces the plan's 1,075 orders/store/day, 15.6% take rate, about ₹109 cost per order and the -0.2% margin.
A34: Sheets
A35: Inputs: disclosed figures, benchmark, derived figures, assumptions
A36: Model: per-order P&L, fixed cost, break-even
A37: Sensitivity: three live grids (AOV x volume, fee x discount, AOV x rider cost)
A38: Scenarios: base, density up, discount war, lever pack
A39: Tornado: ±10% on each input, ranked, with chart
... A41: Checks: reproduces the plan's figures

Sheet Inputs
A1: Inputs: disclosed figures, derived figures and assumptions
A2: Blue = typed input. Blue on yellow = my assumption (change it). Black = formula. Green = link to another sheet.
A4: Item | B4: Value | C4: Unit | D4: Source or note
A5: A. Disclosed: Swiggy Instamart, Q1 FY27 (Apr to Jun 2026)
A6: Instamart GOV | B6: 7907 | C6: ₹ crore | D6: Swiggy Q1 FY27 shareholders' letter and KPI databook
A7: Orders | B7: 114.5 | C7: million | D7: Swiggy Q1 FY27 shareholders' letter and KPI databook
A8: Average order value (AOV) | B8: 691 | C8: ₹ | D8: Swiggy Q1 FY27 shareholders' letter and KPI databook
A9: Adjusted revenue per order | B9: 108 | C9: ₹ | D9: Swiggy Q1 FY27 shareholders' letter and KPI databook
A10: Contribution margin | B10: -0.002 | C10: % of GOV | D10: Swiggy Q1 FY27: contribution is -0.2% of GOV
A11: Dark stores | B11: 1171 | C11: stores | D11: Swiggy Q1 FY27 shareholders' letter and KPI databook
A12: Total store area | B12: 4.92 | C12: million sq ft | D12: Swiggy Q1 FY27 shareholders' letter and KPI databook
A13: Days in quarter (1 Apr to 30 Jun) | B13: 91 | C13: days | D13: 30 + 31 + 30
A15: B. Benchmark, for reference only: Blinkit (Eternal Q1 FY27)
A16: Blinkit net AOV (NAOV) | B16: 518 | C16: ₹ | D16: Eternal Q1 FY27 results; MediaNama; INDmoney
A17: Blinkit stores | B17: 2443 | C17: stores | D17: Eternal Q1 FY27 results; MediaNama; INDmoney
A18: Blinkit contribution | B18: 0.053 | C18: % of NOV | D18: Eternal Q1 FY27 results; MediaNama; INDmoney
A19: Blinkit inventory losses | B19: 0.018 | C19: % of NOV | D19: Eternal Q1 FY27 results; MediaNama; INDmoney
A21: C. Derived from the disclosures (formulas)
A22: Orders per store per day | B22: =B7*1000000/(B11*B13) -> 1074.5019 | C22: orders | D22: Orders / (stores x days). The plan says about 1,075.
A23: Take rate (adjusted revenue / AOV) | B23: =B9/B8 -> 0.15629522 | C23: % of AOV | D23: The plan says 15.6%.
A24: Average store size | B24: =B12*1000000/B11 -> 4201.5371 | C24: sq ft | D24: The plan says about 4,200 sq ft.
A25: Total cost per order (revenue minus contribution) | B25: =B9-B10*B8 -> 109.382 | C25: ₹ | D25: Adjusted revenue less contribution (contribution = -0.2% x AOV = -₹1.38 per order). The plan says about ₹109.
A26: GOV rebuilt from orders x AOV | B26: =B7*B8/10 -> 7911.95 | C26: ₹ crore | D26: Cross-check against the reported GOV in B6.
A28: D. My assumptions (public data does not split these; change the yellow cells)
A29: Delivery + handling fee charged per order | B29: 12 | C29: ₹ | D29: ASSUMPTION. Not separately disclosed.
A30: Ad income per order | B30: 10 | C30: ₹ | D30: ASSUMPTION. Not separately disclosed.
A31: Discounts funded by Instamart per order | B31: 6 | C31: ₹ | D31: ASSUMPTION. Not separately disclosed.
A32: Rider / last-mile cost per order | B32: 45 | C32: ₹ | D32: ASSUMPTION. Typical quick-commerce range; not disclosed.
A33: Picking and packing labour per order | B33: 15 | C33: ₹ | D33: ASSUMPTION. Not disclosed.
A34: Packaging per order | B34: 6 | C34: ₹ | D34: ASSUMPTION. Not disclosed.
A35: Payment gateway cost | B35: 0.012 | C35: % of AOV | D35: ASSUMPTION. Not disclosed.
A36: Wastage and shrink | B36: 0.012 | C36: % of AOV | D36: ASSUMPTION. Blinkit discloses inventory losses of 1.8% of NOV (B19) as a reference point.
A38: E. Calibration: makes the model reproduce the disclosed ₹108 revenue per order
A39: Calibrated product margin (commission / trading margin) | B39: =(B9-B29-B30+B31)/B8 -> 0.13314038 | C39: % of AOV | D39: Solved so that margin + fee + ad income - discounts = disclosed ₹108 at the disclosed AOV.
A41: F. Fixed-cost cross-check (bottom-up guess, shown against the calibrated figure on the Model sheet)
A42: Rent per sq ft per month | B42: 100 | C42: ₹ | D42: ASSUMPTION. Rough micro-warehouse rent; not disclosed.
A43: Fixed staff per store per month | B43: 250000 | C43: ₹ | D43: ASSUMPTION. Store manager, supervisors, security, base shifts; not disclosed.
A44: Power, internet, maintenance per store per month | B44: 80000 | C44: ₹ | D44: ASSUMPTION. Not disclosed.
A45: Bottom-up fixed cost per store per month | B45: =B42*B24+B43+B44 -> 750153.71 | C45: ₹ | D45: Rent x store size + staff + power. Only a cross-check; the model uses the calibrated fixed cost.
A47: G. Model settings
...

Sheet Model
A1: Model: one order, one store, then all 1,171 stores (base case)
A2: Everything here is a formula. Rupee amounts per order unless the label says otherwise.
A3: Line | B3: Value | C3: How it is built
A4: AOV (₹) | B4: =Inputs!B8 -> 691 | C4: Disclosed.
A5: Product margin (₹) | B5: =Inputs!B39*B4 -> 92 | C5: Calibrated margin % x AOV.
A6: Delivery + handling fee (₹) | B6: =Inputs!B29 -> 12 | C6: Assumption.
A7: Ad income (₹) | B7: =Inputs!B30 -> 10 | C7: Assumption.
A8: Discounts (₹) | B8: =-Inputs!B31 -> -6 | C8: Assumption, shown as a deduction.
A9: Revenue per order (₹) | B9: =SUM(B5:B8) -> 108 | C9: Reproduces the disclosed ₹108.
A10: Variable costs
A11: Rider / last-mile (₹) | B11: =-Inputs!B32 -> -45 | C11: Variable. Assumption.
A12: Picking and packing (₹) | B12: =-Inputs!B33 -> -15 | C12: Variable. Assumption.
A13: Packaging (₹) | B13: =-Inputs!B34 -> -6 | C13: Variable. Assumption.
A14: Payment gateway (₹) | B14: =-Inputs!B35*B4 -> -8.292 | C14: Variable: % of AOV.
A15: Wastage and shrink (₹) | B15: =-Inputs!B36*B4 -> -8.292 | C15: Variable: % of AOV.
A16: Variable cost per order (₹) | B16: =SUM(B11:B15) -> -82.584 | C16: Sum of the five variable lines.
A17: Unit contribution before fixed cost (₹ per order) | B17: =B9+B16 -> 25.416 | C17: Revenue less variable cost. What each extra order adds.
A18: Fixed cost, calibrated to the disclosed total
A19: Total cost per order, disclosed (₹) | B19: =Inputs!B25 -> 109.382 | C19: Revenue less contribution.
A20: Implied fixed cost per order at today's volume (₹) | B20: =B19+B16 -> 26.798 | C20: Total cost less variable cost (B16 is negative).
A21: Orders per store per day | B21: =Inputs!B22 -> 1074.5019 | C21: From the disclosures.
A22: Fixed cost per store per day (₹) | B22: =B20*B21 -> 28794.503 | C22: Calibrated: what the disclosed total cost leaves for fixed cost.
A23: Fixed cost per store per month (₹) | B23: =B22*Inputs!B48 -> 863835.08 | C23: Compare with the bottom-up guess on the Inputs sheet.
A24: Result at today's volume
A25: Contribution per order after fixed cost (₹) | B25: =B17-B20 -> -1.382 | C25: Should equal the disclosed -0.2% of AOV.
A26: Contribution margin (% of GOV) | B26: =B25/B4 -> -0.002 | C26: Check: equals the disclosed -0.2%.
A27: Contribution per store per day (₹) | B27: =B25*B21 -> -1484.9617
A28: Contribution per store per month (₹) | B28: =B27*Inputs!B48 -> -44548.85
A29: Contribution, all stores, per quarter (₹ crore) | B29: =B25*Inputs!B7/10 -> -15.8239 | C29: Contribution per order x orders (million) / 10 = ₹ crore.
A30: Break-even
A31: Break-even orders per store per day | B31: =B22/B17 -> 1132.9282 | C31: Fixed cost per day / unit contribution. Same answer Goal Seek would find.
A32: Increase needed vs today | B32: =B31/B21-1 -> 0.054375197
A33: Orders per store per day needed for the target margin | B33: =IF(B17-Inputs!B49*B4<=0,"Not reachable by volume alone",B22/(B17-Inputs!B49*B4)) -> 2483.141 | C33: Fixed cost per day / (unit contribution - target margin x AOV).
A34: Increase needed vs today (target margin) | B34: =IF(ISNUMBER(B33),B33/B21-1,"n/a") -> 1.3109693
A35: Cross-check
A36: Bottom-up fixed cost per store per month (₹) | B36: =Inputs!B45 -> 750153.71 | C36: My guess from rent, staff and power.
A37: Calibrated as a share of the bottom-up guess | B37: =B23/B36 -> 1.1515441 | C37: Above 100% means the guess misses some fixed cost (overheads, depreciation).

Sheet Sensitivity
A1: Sensitivity grids (live formulas)
A2: Each cell recomputes the full model. Product margin % of AOV is held constant. The base case is the middle cell in each grid. Green, then red = better, then worse.
A4: Grid 1. Contribution margin (% of GOV): AOV down the side, orders per store per day across the top
B5: AOV ₹ \ orders/day | C5: 700 | D5: 900 | E5: =ROUND(Inputs!B22,0) -> 1075 | F5: 1300 | G5: 1600 | H5: 2000 | I5: 2500
B6: 518 | C6: =(($B6*Inputs!$B$39+Inputs!$B$29+Inputs!$B$30-Inputs!$B$31-Inputs!$B$32-Inputs!$B$33-Inputs!$B$34-$B6*(Inputs!$B$35+Inputs!$B$36))-Model!$B$22/C$5)/$B6 -> -0.066795925 | D6: =(($B6*Inputs!$B$39+Inputs!$B$29+Inputs!$B$30-Inputs!$B$31-Inputs!$B$32-Inputs!$B$33-Inputs!$B$34-$B6*(Inputs!$B$35+Inputs!$B$36))-Model!$B$22/D$5)/$B6 -> -0.04914899 | E6: =(($B6*Inputs!$B$39+Inputs!$B$29+Inputs!$B$30-Inputs!$B$31-Inputs!$B$32-Inputs!$B$33-Inputs!$B$34-$B6*(Inputs!$B$35+Inputs!$B$36))-Model!$B$22/E$5)/$B6 -> -0.039094342 | F6: =(($B6*Inputs!$B$39+Inputs!$B$29+Inputs!$B$30-Inputs!$B$31-Inputs!$B$32-Inputs!$B$33-Inputs!$B$34-$B6*(Inputs!$B$35+Inputs!$B$36))-Model!$B$22/F$5)/$B6 -> -0.030144599 | G6: =(($B6*Inputs!$B$39+Inputs!$B$29+Inputs!$B$30-Inputs!$B$31-Inputs!$B$32-Inputs!$B$33-Inputs!$B$34-$B6*(Inputs!$B$35+Inputs!$B$36))-Model!$B$22/G$5)/$B6 -> -0.022127122 | H6: =(($B6*Inputs!$B$39+Inputs!$B$29+Inputs!$B$30-Inputs!$B$31-Inputs!$B$32-Inputs!$B$33-Inputs!$B$34-$B6*(Inputs!$B$35+Inputs!$B$36))-Model!$B$22/H$5)/$B6 -> -0.015178642 | I6: =(($B6*Inputs!$B$39+Inputs!$B$29+Inputs!$B$30-Inputs!$B$31-Inputs!$B$32-Inputs!$B$33-Inputs!$B$34-$B6*(Inputs!$B$35+Inputs!$B$36))-Model!$B$22/I$5)/$B6 -> -0.0096198575
B7: 600 | C7: =(($B7*Inputs!$B$39+Inputs!$B$29+Inputs!$B$30-Inputs!$B$31-Inputs!$B$32-Inputs!$B$33-Inputs!$B$34-$B7*(Inputs!$B$35+Inputs!$B$36))-Model!$B$22/C$5)/$B7 -> -0.042751297 | D7: =(($B7*Inputs!$B$39+Inputs!$B$29+Inputs!$B$30-Inputs!$B$31-Inputs!$B$32-Inputs!$B$33-Inputs!$B$34-$B7*(Inputs!$B$35+Inputs!$B$36))-Model!$B$22/D$5)/$B7 -> -0.02751611 | E7: =(($B7*Inputs!$B$39+Inputs!$B$29+Inputs!$B$30-Inputs!$B$31-Inputs!$B$32-Inputs!$B$33-Inputs!$B$34-$B7*(Inputs!$B$35+Inputs!$B$36))-Model!$B$22/E$5)/$B7 -> -0.018835597 | F7: =(($B7*Inputs!$B$39+Inputs!$B$29+Inputs!$B$30-Inputs!$B$31-Inputs!$B$32-Inputs!$B$33-Inputs!$B$34-$B7*(Inputs!$B$35+Inputs!$B$36))-Model!$B$22/F$5)/$B7 -> -0.011108986 | G7: =(($B7*Inputs!$B$39+Inputs!$B$29+Inputs!$B$30-Inputs!$B$31-Inputs!$B$32-Inputs!$B$33-Inputs!$B$34-$B7*(Inputs!$B$35+Inputs!$B$36))-Model!$B$22/G$5)/$B7 -> -0.0041872307 | H7: =(($B7*Inputs!$B$39+Inputs!$B$29+Inputs!$B$30-Inputs!$B$31-Inputs!$B$32-Inputs!$B$33-Inputs!$B$34-$B7*(Inputs!$B$35+Inputs!$B$36))-Model!$B$22/H$5)/$B7 -> 0.001811624 | I7: =(($B7*Inputs!$B$39+Inputs!$B$29+Inputs!$B$30-Inputs!$B$31-Inputs!$B$32-Inputs!$B$33-Inputs!$B$34-$B7*(Inputs!$B$35+Inputs!$B$36))-Model!$B$22/I$5)/$B7 -> 0.0066107078
B8: =Inputs!B8 -> 691 | C8: =(($B8*Inputs!$B$39+Inputs!$B$29+Inputs!$B$30-Inputs!$B$31-Inputs!$B$32-Inputs!$B$33-Inputs!$B$34-$B8*(Inputs!$B$35+Inputs!$B$36))-Model!$B$22/C$5)/$B8 -> -0.022748197 | D8: =(($B8*Inputs!$B$39+Inputs!$B$29+Inputs!$B$30-Inputs!$B$31-Inputs!$B$32-Inputs!$B$33-Inputs!$B$34-$B8*(Inputs!$B$35+Inputs!$B$36))-Model!$B$22/D$5)/$B8 -> -0.0095193804 | E8: =(($B8*Inputs!$B$39+Inputs!$B$29+Inputs!$B$30-Inputs!$B$31-Inputs!$B$32-Inputs!$B$33-Inputs!$B$34-$B8*(Inputs!$B$35+Inputs!$B$36))-Model!$B$22/E$5)/$B8 -> -0.0019820317 | F8: =(($B8*Inputs!$B$39+Inputs!$B$29+Inputs!$B$30-Inputs!$B$31-Inputs!$B$32-Inputs!$B$33-Inputs!$B$34-$B8*(Inputs!$B$35+Inputs!$B$36))-Model!$B$22/F$5)/$B8 -> 0.004727037 | G8: =(($B8*Inputs!$B$39+Inputs!$B$29+Inputs!$B$30-Inputs!$B$31-Inputs!$B$32-Inputs!$B$33-Inputs!$B$34-$B8*(Inputs!$B$35+Inputs!$B$36))-Model!$B$22/G$5)/$B8 -> 0.010737244 | H8: =(($B8*Inputs!$B$39+Inputs!$B$29+Inputs!$B$30-Inputs!$B$31-Inputs!$B$32-Inputs!$B$33-Inputs!$B$34-$B8*(Inputs!$B$35+Inputs!$B$36))-Model!$B$22/H$5)/$B8 -> 0.015946091 | I8: =(($B8*Inputs!$B$39+Inputs!$B$29+Inputs!$B$30-Inputs!$B$31-Inputs!$B$32-Inputs!$B$33-Inputs!$B$34-$B8*(Inputs!$B$35+Inputs!$B$36))-Model!$B$22/I$5)/$B8 -> 0.020113168
B9: 800 | C9: =(($B9*Inputs!$B$39+Inputs!$B$29+Inputs!$B$30-Inputs!$B$31-Inputs!$B$32-Inputs!$B$33-Inputs!$B$34-$B9*(Inputs!$B$35+Inputs!$B$36))-Model!$B$22/C$5)/$B9 -> -0.0047783785 | D9: =(($B9*Inputs!$B$39+Inputs!$B$29+Inputs!$B$30-Inputs!$B$31-Inputs!$B$32-Inputs!$B$33-Inputs!$B$34-$B9*(Inputs!$B$35+Inputs!$B$36))-Model!$B$22/D$5)/$B9 -> 0.0066480114 | E9: =(($B9*Inputs!$B$39+Inputs!$B$29+Inputs!$B$30-Inputs!$B$31-Inputs!$B$32-Inputs!$B$33-Inputs!$B$34-$B9*(Inputs!$B$35+Inputs!$B$36))-Model!$B$22/E$5)/$B9 -> 0.013158396 | F9: =(($B9*Inputs!$B$39+Inputs!$B$29+Inputs!$B$30-Inputs!$B$31-Inputs!$B$32-Inputs!$B$33-Inputs!$B$34-$B9*(Inputs!$B$35+Inputs!$B$36))-Model!$B$22/F$5)/$B9 -> 0.018953354 | G9: =(($B9*Inputs!$B$39+Inputs!$B$29+Inputs!$B$30-Inputs!$B$31-Inputs!$B$32-Inputs!$B$33-Inputs!$B$34-$B9*(Inputs!$B$35+Inputs!$B$36))-Model!$B$22/G$5)/$B9 -> 0.024144671 | H9: =(($B9*Inputs!$B$39+Inputs!$B$29+Inputs!$B$30-Inputs!$B$31-Inputs!$B$32-Inputs!$B$33-Inputs!$B$34-$B9*(Inputs!$B$35+Inputs!$B$36))-Model!$B$22/H$5)/$B9 -> 0.028643812 | I9: =(($B9*Inputs!$B$39+Inputs!$B$29+Inputs!$B$30-Inputs!$B$31-Inputs!$B$32-Inputs!$B$33-Inputs!$B$34-$B9*(Inputs!$B$35+Inputs!$B$36))-Model!$B$22/I$5)/$B9 -> 0.032243125
B10: 900 | C10: =(($B10*Inputs!$B$39+Inputs!$B$29+Inputs!$B$30-Inputs!$B$31-Inputs!$B$32-Inputs!$B$33-Inputs!$B$34-$B10*(Inputs!$B$35+Inputs!$B$36))-Model!$B$22/C$5)/$B10 -> 0.0078792609 | D10: =(($B10*Inputs!$B$39+Inputs!$B$29+Inputs!$B$30-Inputs!$B$31-Inputs!$B$32-Inputs!$B$33-Inputs!$B$34-$B10*(Inputs!$B$35+Inputs!$B$36))-Model!$B$22/D$5)/$B10 -> 0.018036052 | E10: =(($B10*Inputs!$B$39+Inputs!$B$29+Inputs!$B$30-Inputs!$B$31-Inputs!$B$32-Inputs!$B$33-Inputs!$B$34-$B10*(Inputs!$B$35+Inputs!$B$36))-Model!$B$22/E$5)/$B10 -> 0.023823061 | F10: =(($B10*Inputs!$B$39+Inputs!$B$29+Inputs!$B$30-Inputs!$B$31-Inputs!$B$32-Inputs!$B$33-Inputs!$B$34-$B10*(Inputs!$B$35+Inputs!$B$36))-Model!$B$22/F$5)/$B10 -> 0.028974135 | G10: =(($B10*Inputs!$B$39+Inputs!$B$29+Inputs!$B$30-Inputs!$B$31-Inputs!$B$32-Inputs!$B$33-Inputs!$B$34-$B10*(Inputs!$B$35+Inputs!$B$36))-Model!$B$22/G$5)/$B10 -> 0.033588638 | H10: =(($B10*Inputs!$B$39+Inputs!$B$29+Inputs!$B$30-Inputs!$B$31-Inputs!$B$32-Inputs!$B$33-Inputs!$B$34-$B10*(Inputs!$B$35+Inputs!$B$36))-Model!$B$22/H$5)/$B10 -> 0.037587875 | I10: =(($B10*Inputs!$B$39+Inputs!$B$29+Inputs!$B$30-Inputs!$B$31-Inputs!$B$32-Inputs!$B$33-Inputs!$B$34-$B10*(Inputs!$B$35+Inputs!$B$36))-Model!$B$22/I$5)/$B10 -> 0.040787264
B11: AOV 518 = Blinkit's NAOV, for comparison. Blinkit's disclosed contribution is 5.3% of NOV.
A13: Grid 2. Contribution margin (% of GOV): delivery fee down the side, discount per order across the top
B14: Fee ₹ \ discount ₹ | C14: 0 | D14: 3 | E14: =Inputs!B31 -> 6 | F14: 10 | G14: 15 | H14: 20 | I14: 30
B15: 0 | C15: =((Inputs!$B$8*Inputs!$B$39+$B15+Inputs!$B$30-C$14-Inputs!$B$32-Inputs!$B$33-Inputs!$B$34-Inputs!$B$8*(Inputs!$B$35+Inputs!$B$36))-Model!$B$22/Inputs!$B$22)/Inputs!$B$8 -> -0.010683068 | D15: =((Inputs!$B$8*Inputs!$B$39+$B15+Inputs!$B$30-D$14-Inputs!$B$32-Inputs!$B$33-Inputs!$B$34-Inputs!$B$8*(Inputs!$B$35+Inputs!$B$36))-Model!$B$22/Inputs!$B$22)/Inputs!$B$8 -> -0.015024602 | E15: =((Inputs!$B$8*Inputs!$B$39+$B15+Inputs!$B$30-E$14-Inputs!$B$32-Inputs!$B$33-Inputs!$B$34-Inputs!$B$8*(Inputs!$B$35+Inputs!$B$36))-Model!$B$22/Inputs!$B$22)/Inputs!$B$8 -> -0.019366136 | F15: =((Inputs!$B$8*Inputs!$B$39+$B15+Inputs!$B$30-F$14-Inputs!$B$32-Inputs!$B$33-Inputs!$B$34-Inputs!$B$8*(Inputs!$B$35+Inputs!$B$36))-Model!$B$22/Inputs!$B$22)/Inputs!$B$8 -> -0.025154848 | G15: =((Inputs!$B$8*Inputs!$B$39+$B15+Inputs!$B$30-G$14-Inputs!$B$32-Inputs!$B$33-Inputs!$B$34-Inputs!$B$8*(Inputs!$B$35+Inputs!$B$36))-Model!$B$22/Inputs!$B$22)/Inputs!$B$8 -> -0.032390738 | H15: =((Inputs!$B$8*Inputs!$B$39+$B15+Inputs!$B$30-H$14-Inputs!$B$32-Inputs!$B$33-Inputs!$B$34-Inputs!$B$8*(Inputs!$B$35+Inputs!$B$36))-Model!$B$22/Inputs!$B$22)/Inputs!$B$8 -> -0.039626628 | I15: =((Inputs!$B$8*Inputs!$B$39+$B15+Inputs!$B$30-I$14-Inputs!$B$32-Inputs!$B$33-Inputs!$B$34-Inputs!$B$8*(Inputs!$B$35+Inputs!$B$36))-Model!$B$22/Inputs!$B$22)/Inputs!$B$8 -> -0.054098408
B16: =Inputs!B29 -> 12 | C16: =((Inputs!$B$8*Inputs!$B$39+$B16+Inputs!$B$30-C$14-Inputs!$B$32-Inputs!$B$33-Inputs!$B$34-Inputs!$B$8*(Inputs!$B$35+Inputs!$B$36))-Model!$B$22/Inputs!$B$22)/Inputs!$B$8 -> 0.006683068 | D16: =((Inputs!$B$8*Inputs!$B$39+$B16+Inputs!$B$30-D$14-Inputs!$B$32-Inputs!$B$33-Inputs!$B$34-Inputs!$B$8*(Inputs!$B$35+Inputs!$B$36))-Model!$B$22/Inputs!$B$22)/Inputs!$B$8 -> 0.002341534 | E16: =((Inputs!$B$8*Inputs!$B$39+$B16+Inputs!$B$30-E$14-Inputs!$B$32-Inputs!$B$33-Inputs!$B$34-Inputs!$B$8*(Inputs!$B$35+Inputs!$B$36))-Model!$B$22/Inputs!$B$22)/Inputs!$B$8 -> -0.002 | F16: =((Inputs!$B$8*Inputs!$B$39+$B16+Inputs!$B$30-F$14-Inputs!$B$32-Inputs!$B$33-Inputs!$B$34-Inputs!$B$8*(Inputs!$B$35+Inputs!$B$36))-Model!$B$22/Inputs!$B$22)/Inputs!$B$8 -> -0.007788712 | G16: =((Inputs!$B$8*Inputs!$B$39+$B16+Inputs!$B$30-G$14-Inputs!$B$32-Inputs!$B$33-Inputs!$B$34-Inputs!$B$8*(Inputs!$B$35+Inputs!$B$36))-Model!$B$22/Inputs!$B$22)/Inputs!$B$8 -> -0.015024602 | H16: =((Inputs!$B$8*Inputs!$B$39+$B16+Inputs!$B$30-H$14-Inputs!$B$32-Inputs!$B$33-Inputs!$B$34-Inputs!$B$8*(Inputs!$B$35+Inputs!$B$36))-Model!$B$22/Inputs!$B$22)/Inputs!$B$8 -> -0.022260492 | I16: =((Inputs!$B$8*Inputs!$B$39+$B16+Inputs!$B$30-I$14-Inputs!$B$32-Inputs!$B$33-Inputs!$B$34-Inputs!$B$8*(Inputs!$B$35+Inputs!$B$36))-Model!$B$22/Inputs!$B$22)/Inputs!$B$8 -> -0.036732272
B17: 20 | C17: =((Inputs!$B$8*Inputs!$B$39+$B17+Inputs!$B$30-C$14-Inputs!$B$32-Inputs!$B$33-Inputs!$B$34-Inputs!$B$8*(Inputs!$B$35+Inputs!$B$36))-Model!$B$22/Inputs!$B$22)/Inputs!$B$8 -> 0.018260492 | D17: =((Inputs!$B$8*Inputs!$B$39+$B17+Inputs!$B$30-D$14-Inputs!$B$32-Inputs!$B$33-Inputs!$B$34-Inputs!$B$8*(Inputs!$B$35+Inputs!$B$36))-Model!$B$22/Inputs!$B$22)/Inputs!$B$8 -> 0.013918958 | E17: =((Inputs!$B$8*Inputs!$B$39+$B17+Inputs!$B$30-E$14-Inputs!$B$32-Inputs!$B$33-Inputs!$B$34-Inputs!$B$8*(Inputs!$B$35+Inputs!$B$36))-Model!$B$22/Inputs!$B$22)/Inputs!$B$8 -> 0.009577424 | F17: =((Inputs!$B$8*Inputs!$B$39+$B17+Inputs!$B$30-F$14-Inputs!$B$32-Inputs!$B$33-Inputs!$B$34-Inputs!$B$8*(Inputs!$B$35+Inputs!$B$36))-Model!$B$22/Inputs!$B$22)/Inputs!$B$8 -> 0.003788712 | G17: =((Inputs!$B$8*Inputs!$B$39+$B17+Inputs!$B$30-G$14-Inputs!$B$32-Inputs!$B$33-Inputs!$B$34-Inputs!$B$8*(Inputs!$B$35+Inputs!$B$36))-Model!$B$22/Inputs!$B$22)/Inputs!$B$8 -> -0.003447178 | H17: =((Inputs!$B$8*Inputs!$B$39+$B17+Inputs!$B$30-H$14-Inputs!$B$32-Inputs!$B$33-Inputs!$B$34-Inputs!$B$8*(Inputs!$B$35+Inputs!$B$36))-Model!$B$22/Inputs!$B$22)/Inputs!$B$8 -> -0.010683068 | I17: =((Inputs!$B$8*Inputs!$B$39+$B17+Inputs!$B$30-I$14-Inputs!$B$32-Inputs!$B$33-Inputs!$B$34-Inputs!$B$8*(Inputs!$B$35+Inputs!$B$36))-Model!$B$22/Inputs!$B$22)/Inputs!$B$8 -> -0.025154848
B18: 30 | C18: =((Inputs!$B$8*Inputs!$B$39+$B18+Inputs!$B$30-C$14-Inputs!$B$32-Inputs!$B$33-Inputs!$B$34-Inputs!$B$8*(Inputs!$B$35+Inputs!$B$36))-Model!$B$22/Inputs!$B$22)/Inputs!$B$8 -> 0.032732272 | D18: =((Inputs!$B$8*Inputs!$B$39+$B18+Inputs!$B$30-D$14-Inputs!$B$32-Inputs!$B$33-Inputs!$B$34-Inputs!$B$8*(Inputs!$B$35+Inputs!$B$36))-Model!$B$22/Inputs!$B$22)/Inputs!$B$8 -> 0.028390738 | E18: =((Inputs!$B$8*Inputs!$B$39+$B18+Inputs!$B$30-E$14-Inputs!$B$32-Inputs!$B$33-Inputs!$B$34-Inputs!$B$8*(Inputs!$B$35+Inputs!$B$36))-Model!$B$22/Inputs!$B$22)/Inputs!$B$8 -> 0.024049204 | F18: =((Inputs!$B$8*Inputs!$B$39+$B18+Inputs!$B$30-F$14-Inputs!$B$32-Inputs!$B$33-Inputs!$B$34-Inputs!$B$8*(Inputs!$B$35+Inputs!$B$36))-Model!$B$22/Inputs!$B$22)/Inputs!$B$8 -> 0.018260492 | G18: =((Inputs!$B$8*Inputs!$B$39+$B18+Inputs!$B$30-G$14-Inputs!$B$32-Inputs!$B$33-Inputs!$B$34-Inputs!$B$8*(Inputs!$B$35+Inputs!$B$36))-Model!$B$22/Inputs!$B$22)/Inputs!$B$8 -> 0.011024602 | H18: =((Inputs!$B$8*Inputs!$B$39+$B18+Inputs!$B$30-H$14-Inputs!$B$32-Inputs!$B$33-Inputs!$B$34-Inputs!$B$8*(Inputs!$B$35+Inputs!$B$36))-Model!$B$22/Inputs!$B$22)/Inputs!$B$8 -> 0.003788712 | I18: =((Inputs!$B$8*Inputs!$B$39+$B18+Inputs!$B$30-I$14-Inputs!$B$32-Inputs!$B$33-Inputs!$B$34-Inputs!$B$8*(Inputs!$B$35+Inputs!$B$36))-Model!$B$22/Inputs!$B$22)/Inputs!$B$8 -> -0.010683068
B19: 40 | C19: =((Inputs!$B$8*Inputs!$B$39+$B19+Inputs!$B$30-C$14-Inputs!$B$32-Inputs!$B$33-Inputs!$B$34-Inputs!$B$8*(Inputs!$B$35+Inputs!$B$36))-Model!$B$22/Inputs!$B$22)/Inputs!$B$8 -> 0.047204052 | D19: =((Inputs!$B$8*Inputs!$B$39+$B19+Inputs!$B$30-D$14-Inputs!$B$32-Inputs!$B$33-Inputs!$B$34-Inputs!$B$8*(Inputs!$B$35+Inputs!$B$36))-Model!$B$22/Inputs!$B$22)/Inputs!$B$8 -> 0.042862518 | E19: =((Inputs!$B$8*Inputs!$B$39+$B19+Inputs!$B$30-E$14-Inputs!$B$32-Inputs!$B$33-Inputs!$B$34-Inputs!$B$8*(Inputs!$B$35+Inputs!$B$36))-Model!$B$22/Inputs!$B$22)/Inputs!$B$8 -> 0.038520984 | F19: =((Inputs!$B$8*Inputs!$B$39+$B19+Inputs!$B$30-F$14-Inputs!$B$32-Inputs!$B$33-Inputs!$B$34-Inputs!$B$8*(Inputs!$B$35+Inputs!$B$36))-Model!$B$22/Inputs!$B$22)/Inputs!$B$8 -> 0.032732272 | G19: =((Inputs!$B$8*Inputs!$B$39+$B19+Inputs!$B$30-G$14-Inputs!$B$32-Inputs!$B$33-Inputs!$B$34-Inputs!$B$8*(Inputs!$B$35+Inputs!$B$36))-Model!$B$22/Inputs!$B$22)/Inputs!$B$8 -> 0.025496382 | H19: =((Inputs!$B$8*Inputs!$B$39+$B19+Inputs!$B$30-H$14-Inputs!$B$32-Inputs!$B$33-Inputs!$B$34-Inputs!$B$8*(Inputs!$B$35+Inputs!$B$36))-Model!$B$22/Inputs!$B$22)/Inputs!$B$8 -> 0.018260492 | I19: =((Inputs!$B$8*Inputs!$B$39+$B19+Inputs!$B$30-I$14-Inputs!$B$32-Inputs!$B$33-Inputs!$B$34-Inputs!$B$8*(Inputs!$B$35+Inputs!$B$36))-Model!$B$22/Inputs!$B$22)/Inputs!$B$8 -> 0.003788712
B20: 50 | C20: =((Inputs!$B$8*Inputs!$B$39+$B20+Inputs!$B$30-C$14-Inputs!$B$32-Inputs!$B$33-Inputs!$B$34-Inputs!$B$8*(Inputs!$B$35+Inputs!$B$36))-Model!$B$22/Inputs!$B$22)/Inputs!$B$8 -> 0.061675832 | D20: =((Inputs!$B$8*Inputs!$B$39+$B20+Inputs!$B$30-D$14-Inputs!$B$32-Inputs!$B$33-Inputs!$B$34-Inputs!$B$8*(Inputs!$B$35+Inputs!$B$36))-Model!$B$22/Inputs!$B$22)/Inputs!$B$8 -> 0.057334298 | E20: =((Inputs!$B$8*Inputs!$B$39+$B20+Inputs!$B$30-E$14-Inputs!$B$32-Inputs!$B$33-Inputs!$B$34-Inputs!$B$8*(Inputs!$B$35+Inputs!$B$36))-Model!$B$22/Inputs!$B$22)/Inputs!$B$8 -> 0.052992764 | F20: =((Inputs!$B$8*Inputs!$B$39+$B20+Inputs!$B$30-F$14-Inputs!$B$32-Inputs!$B$33-Inputs!$B$34-Inputs!$B$8*(Inputs!$B$35+Inputs!$B$36))-Model!$B$22/Inputs!$B$22)/Inputs!$B$8 -> 0.047204052 | G20: =((Inputs!$B$8*Inputs!$B$39+$B20+Inputs!$B$30-G$14-Inputs!$B$32-Inputs!$B$33-Inputs!$B$34-Inputs!$B$8*(Inputs!$B$35+Inputs!$B$36))-Model!$B$22/Inputs!$B$22)/Inputs!$B$8 -> 0.039968162 | H20: =((Inputs!$B$8*Inputs!$B$39+$B20+Inputs!$B$30-H$14-Inputs!$B$32-Inputs!$B$33-Inputs!$B$34-Inputs!$B$8*(Inputs!$B$35+Inputs!$B$36))-Model!$B$22/Inputs!$B$22)/Inputs!$B$8 -> 0.032732272 | I20: =((Inputs!$B$8*Inputs!$B$39+$B20+Inputs!$B$30-I$14-Inputs!$B$32-Inputs!$B$33-Inputs!$B$34-Inputs!$B$8*(Inputs!$B$35+Inputs!$B$36))-Model!$B$22/Inputs!$B$22)/Inputs!$B$8 -> 0.018260492
A22: Grid 3. Break-even orders per store per day: AOV down the side, rider cost per order across the top
B23: AOV ₹ \ rider ₹ | C23: 35 | D23: 40 | E23: =Inputs!B32 -> 45 | F23: 50 | G23: 55 | H23: 60
B24: 518 | C24: =IF(($B24*Inputs!$B$39+Inputs!$B$29+Inputs!$B$30-Inputs!$B$31-C$23-Inputs!$B$33-Inputs!$B$34-$B24*(Inputs!$B$35+Inputs!$B$36))<=0,"n/a",Model!$B$22/($B24*Inputs!$B$39+Inputs!$B$29+Inputs!$B$30-Inputs!$B$31-C$23-Inputs!$B$33-Inputs!$B$34-$B24*(Inputs!$B$35+Inputs!$B$36))) -> 1741.4575 | D24: =IF(($B24*Inputs!$B$39+Inputs!$B$29+Inputs!$B$30-Inputs!$B$31-D$23-Inputs!$B$33-Inputs!$B$34-$B24*(Inputs!$B$35+Inputs!$B$36))<=0,"n/a",Model!$B$22/($B24*Inputs!$B$39+Inputs!$B$29+Inputs!$B$30-Inputs!$B$31-D$23-Inputs!$B$33-Inputs!$B$34-$B24*(Inputs!$B$35+Inputs!$B$36))) -> 2496.3341 | E24: =IF(($B24*Inputs!$B$39+Inputs!$B$29+Inputs!$B$30-Inputs!$B$31-E$23-Inputs!$B$33-Inputs!$B$34-$B24*(Inputs!$B$35+Inputs!$B$36))<=0,"n/a",Model!$B$22/($B24*Inputs!$B$39+Inputs!$B$29+Inputs!$B$30-Inputs!$B$31-E$23-Inputs!$B$33-Inputs!$B$34-$B24*(Inputs!$B$35+Inputs!$B$36))) -> 4406.39 | F24: =IF(($B24*Inputs!$B$39+Inputs!$B$29+Inputs!$B$30-Inputs!$B$31-F$23-Inputs!$B$33-Inputs!$B$34-$B24*(Inputs!$B$35+Inputs!$B$36))<=0,"n/a",Model!$B$22/($B24*Inputs!$B$39+Inputs!$B$29+Inputs!$B$30-Inputs!$B$31-F$23-Inputs!$B$33-Inputs!$B$34-$B24*(Inputs!$B$35+Inputs!$B$36))) -> 18762.118 | G24: =IF(($B24*Inputs!$B$39+Inputs!$B$29+Inputs!$B$30-Inputs!$B$31-G$23-Inputs!$B$33-Inputs!$B$34-$B24*(Inputs!$B$35+Inputs!$B$36))<=0,"n/a",Model!$B$22/($B24*Inputs!$B$39+Inputs!$B$29+Inputs!$B$30-Inputs!$B$31-G$23-Inputs!$B$33-Inputs!$B$34-$B24*(Inputs!$B$35+Inputs!$B$36))) -> n/a | H24: =IF(($B24*Inputs!$B$39+Inputs!$B$29+Inputs!$B$30-Inputs!$B$31-H$23-Inputs!$B$33-Inputs!$B$34-$B24*(Inputs!$B$35+Inputs!$B$36))<=0,"n/a",Model!$B$22/($B24*Inputs!$B$39+Inputs!$B$29+Inputs!$B$30-Inputs!$B$31-H$23-Inputs!$B$33-Inputs!$B$34-$B24*(Inputs!$B$35+Inputs!$B$36))) -> n/a
B25: 600 | C25: =IF(($B25*Inputs!$B$39+Inputs!$B$29+Inputs!$B$30-Inputs!$B$31-C$23-Inputs!$B$33-Inputs!$B$34-$B25*(Inputs!$B$35+Inputs!$B$36))<=0,"n/a",Model!$B$22/($B25*Inputs!$B$39+Inputs!$B$29+Inputs!$B$30-Inputs!$B$31-C$23-Inputs!$B$33-Inputs!$B$34-$B25*(Inputs!$B$35+Inputs!$B$36))) -> 1129.8951 | D25: =IF(($B25*Inputs!$B$39+Inputs!$B$29+Inputs!$B$30-Inputs!$B$31-D$23-Inputs!$B$33-Inputs!$B$34-$B25*(Inputs!$B$35+Inputs!$B$36))<=0,"n/a",Model!$B$22/($B25*Inputs!$B$39+Inputs!$B$29+Inputs!$B$30-Inputs!$B$31-D$23-Inputs!$B$33-Inputs!$B$34-$B25*(Inputs!$B$35+Inputs!$B$36))) -> 1405.6915 | E25: =IF(($B25*Inputs!$B$39+Inputs!$B$29+Inputs!$B$30-Inputs!$B$31-E$23-Inputs!$B$33-Inputs!$B$34-$B25*(Inputs!$B$35+Inputs!$B$36))<=0,"n/a",Model!$B$22/($B25*Inputs!$B$39+Inputs!$B$29+Inputs!$B$30-Inputs!$B$31-E$23-Inputs!$B$33-Inputs!$B$34-$B25*(Inputs!$B$35+Inputs!$B$36))) -> 1859.6024 | F25: =IF(($B25*Inputs!$B$39+Inputs!$B$29+Inputs!$B$30-Inputs!$B$31-F$23-Inputs!$B$33-Inputs!$B$34-$B25*(Inputs!$B$35+Inputs!$B$36))<=0,"n/a",Model!$B$22/($B25*Inputs!$B$39+Inputs!$B$29+Inputs!$B$30-Inputs!$B$31-F$23-Inputs!$B$33-Inputs!$B$34-$B25*(Inputs!$B$35+Inputs!$B$36))) -> 2746.4596 | G25: =IF(($B25*Inputs!$B$39+Inputs!$B$29+Inputs!$B$30-Inputs!$B$31-G$23-Inputs!$B$33-Inputs!$B$34-$B25*(Inputs!$B$35+Inputs!$B$36))<=0,"n/a",Model!$B$22/($B25*Inputs!$B$39+Inputs!$B$29+Inputs!$B$30-Inputs!$B$31-G$23-Inputs!$B$33-Inputs!$B$34-$B25*(Inputs!$B$35+Inputs!$B$36))) -> 5250.4226 | H25: =IF(($B25*Inputs!$B$39+Inputs!$B$29+Inputs!$B$30-Inputs!$B$31-H$23-Inputs!$B$33-Inputs!$B$34-$B25*(Inputs!$B$35+Inputs!$B$36))<=0,"n/a",Model!$B$22/($B25*Inputs!$B$39+Inputs!$B$29+Inputs!$B$30-Inputs!$B$31-H$23-Inputs!$B$33-Inputs!$B$34-$B25*(Inputs!$B$35+Inputs!$B$36))) -> 59465.037
B26: =Inputs!B8 -> 691 | C26: =IF(($B26*Inputs!$B$39+Inputs!$B$29+Inputs!$B$30-Inputs!$B$31-C$23-Inputs!$B$33-Inputs!$B$34-$B26*(Inputs!$B$35+Inputs!$B$36))<=0,"n/a",Model!$B$22/($B26*Inputs!$B$39+Inputs!$B$29+Inputs!$B$30-Inputs!$B$31-C$23-Inputs!$B$33-Inputs!$B$34-$B26*(Inputs!$B$35+Inputs!$B$36))) -> 813.03656 | D26: =IF(($B26*Inputs!$B$39+Inputs!$B$29+Inputs!$B$30-Inputs!$B$31-D$23-Inputs!$B$33-Inputs!$B$34-$B26*(Inputs!$B$35+Inputs!$B$36))<=0,"n/a",Model!$B$22/($B26*Inputs!$B$39+Inputs!$B$29+Inputs!$B$30-Inputs!$B$31-D$23-Inputs!$B$33-Inputs!$B$34-$B26*(Inputs!$B$35+Inputs!$B$36))) -> 946.68933 | E26: =IF(($B26*Inputs!$B$39+Inputs!$B$29+Inputs!$B$30-Inputs!$B$31-E$23-Inputs!$B$33-Inputs!$B$34-$B26*(Inputs!$B$35+Inputs!$B$36))<=0,"n/a",Model!$B$22/($B26*Inputs!$B$39+Inputs!$B$29+Inputs!$B$30-Inputs!$B$31-E$23-Inputs!$B$33-Inputs!$B$34-$B26*(Inputs!$B$35+Inputs!$B$36))) -> 1132.9282 | F26: =IF(($B26*Inputs!$B$39+Inputs!$B$29+Inputs!$B$30-Inputs!$B$31-F$23-Inputs!$B$33-Inputs!$B$34-$B26*(Inputs!$B$35+Inputs!$B$36))<=0,"n/a",Model!$B$22/($B26*Inputs!$B$39+Inputs!$B$29+Inputs!$B$30-Inputs!$B$31-F$23-Inputs!$B$33-Inputs!$B$34-$B26*(Inputs!$B$35+Inputs!$B$36))) -> 1410.389 | G26: =IF(($B26*Inputs!$B$39+Inputs!$B$29+Inputs!$B$30-Inputs!$B$31-G$23-Inputs!$B$33-Inputs!$B$34-$B26*(Inputs!$B$35+Inputs!$B$36))<=0,"n/a",Model!$B$22/($B26*Inputs!$B$39+Inputs!$B$29+Inputs!$B$30-Inputs!$B$31-G$23-Inputs!$B$33-Inputs!$B$34-$B26*(Inputs!$B$35+Inputs!$B$36))) -> 1867.8323 | H26: =IF(($B26*Inputs!$B$39+Inputs!$B$29+Inputs!$B$30-Inputs!$B$31-H$23-Inputs!$B$33-Inputs!$B$34-$B26*(Inputs!$B$35+Inputs!$B$36))<=0,"n/a",Model!$B$22/($B26*Inputs!$B$39+Inputs!$B$29+Inputs!$B$30-Inputs!$B$31-H$23-Inputs!$B$33-Inputs!$B$34-$B26*(Inputs!$B$35+Inputs!$B$36))) -> 2764.4492
B27: 800 | C27: =IF(($B27*Inputs!$B$39+Inputs!$B$29+Inputs!$B$30-Inputs!$B$31-C$23-Inputs!$B$33-Inputs!$B$34-$B27*(Inputs!$B$35+Inputs!$B$36))<=0,"n/a",Model!$B$22/($B27*Inputs!$B$39+Inputs!$B$29+Inputs!$B$30-Inputs!$B$31-C$23-Inputs!$B$33-Inputs!$B$34-$B27*(Inputs!$B$35+Inputs!$B$36))) -> 608.60499 | D27: =IF(($B27*Inputs!$B$39+Inputs!$B$29+Inputs!$B$30-Inputs!$B$31-D$23-Inputs!$B$33-Inputs!$B$34-$B27*(Inputs!$B$35+Inputs!$B$36))<=0,"n/a",Model!$B$22/($B27*Inputs!$B$39+Inputs!$B$29+Inputs!$B$30-Inputs!$B$31-D$23-Inputs!$B$33-Inputs!$B$34-$B27*(Inputs!$B$35+Inputs!$B$36))) -> 680.5232 | E27: =IF(($B27*Inputs!$B$39+Inputs!$B$29+Inputs!$B$30-Inputs!$B$31-E$23-Inputs!$B$33-Inputs!$B$34-$B27*(Inputs!$B$35+Inputs!$B$36))<=0,"n/a",Model!$B$22/($B27*Inputs!$B$39+Inputs!$B$29+Inputs!$B$30-Inputs!$B$31-E$23-Inputs!$B$33-Inputs!$B$34-$B27*(Inputs!$B$35+Inputs!$B$36))) -> 771.71608 | F27: =IF(($B27*Inputs!$B$39+Inputs!$B$29+Inputs!$B$30-Inputs!$B$31-F$23-Inputs!$B$33-Inputs!$B$34-$B27*(Inputs!$B$35+Inputs!$B$36))<=0,"n/a",Model!$B$22/($B27*Inputs!$B$39+Inputs!$B$29+Inputs!$B$30-Inputs!$B$31-F$23-Inputs!$B$33-Inputs!$B$34-$B27*(Inputs!$B$35+Inputs!$B$36))) -> 891.1313 | G27: =IF(($B27*Inputs!$B$39+Inputs!$B$29+Inputs!$B$30-Inputs!$B$31-G$23-Inputs!$B$33-Inputs!$B$34-$B27*(Inputs!$B$35+Inputs!$B$36))<=0,"n/a",Model!$B$22/($B27*Inputs!$B$39+Inputs!$B$29+Inputs!$B$30-Inputs!$B$31-G$23-Inputs!$B$33-Inputs!$B$34-$B27*(Inputs!$B$35+Inputs!$B$36))) -> 1054.2686 | H27: =IF(($B27*Inputs!$B$39+Inputs!$B$29+Inputs!$B$30-Inputs!$B$31-H$23-Inputs!$B$33-Inputs!$B$34-$B27*(Inputs!$B$35+Inputs!$B$36))<=0,"n/a",Model!$B$22/($B27*Inputs!$B$39+Inputs!$B$29+Inputs!$B$30-Inputs!$B$31-H$23-Inputs!$B$33-Inputs!$B$34-$B27*(Inputs!$B$35+Inputs!$B$36))) -> 1290.5214
B28: 900 | C28: =IF(($B28*Inputs!$B$39+Inputs!$B$29+Inputs!$B$30-Inputs!$B$31-C$23-Inputs!$B$33-Inputs!$B$34-$B28*(Inputs!$B$35+Inputs!$B$36))<=0,"n/a",Model!$B$22/($B28*Inputs!$B$39+Inputs!$B$29+Inputs!$B$30-Inputs!$B$31-C$23-Inputs!$B$33-Inputs!$B$34-$B28*(Inputs!$B$35+Inputs!$B$36))) -> 494.5271 | D28: =IF(($B28*Inputs!$B$39+Inputs!$B$29+Inputs!$B$30-Inputs!$B$31-D$23-Inputs!$B$33-Inputs!$B$34-$B28*(Inputs!$B$35+Inputs!$B$36))<=0,"n/a",Model!$B$22/($B28*Inputs!$B$39+Inputs!$B$29+Inputs!$B$30-Inputs!$B$31-D$23-Inputs!$B$33-Inputs!$B$34-$B28*(Inputs!$B$35+Inputs!$B$36))) -> 540.98222 | E28: =IF(($B28*Inputs!$B$39+Inputs!$B$29+Inputs!$B$30-Inputs!$B$31-E$23-Inputs!$B$33-Inputs!$B$34-$B28*(Inputs!$B$35+Inputs!$B$36))<=0,"n/a",Model!$B$22/($B28*Inputs!$B$39+Inputs!$B$29+Inputs!$B$30-Inputs!$B$31-E$23-Inputs!$B$33-Inputs!$B$34-$B28*(Inputs!$B$35+Inputs!$B$36))) -> 597.07006 | F28: =IF(($B28*Inputs!$B$39+Inputs!$B$29+Inputs!$B$30-Inputs!$B$31-F$23-Inputs!$B$33-Inputs!$B$34-$B28*(Inputs!$B$35+Inputs!$B$36))<=0,"n/a",Model!$B$22/($B28*Inputs!$B$39+Inputs!$B$29+Inputs!$B$30-Inputs!$B$31-F$23-Inputs!$B$33-Inputs!$B$34-$B28*(Inputs!$B$35+Inputs!$B$36))) -> 666.13328 | G28: =IF(($B28*Inputs!$B$39+Inputs!$B$29+Inputs!$B$30-Inputs!$B$31-G$23-Inputs!$B$33-Inputs!$B$34-$B28*(Inputs!$B$35+Inputs!$B$36))<=0,"n/a",Model!$B$22/($B28*Inputs!$B$39+Inputs!$B$29+Inputs!$B$30-Inputs!$B$31-G$23-Inputs!$B$33-Inputs!$B$34-$B28*(Inputs!$B$35+Inputs!$B$36))) -> 753.26342 | H28: =IF(($B28*Inputs!$B$39+Inputs!$B$29+Inputs!$B$30-Inputs!$B$31-H$23-Inputs!$B$33-Inputs!$B$34-$B28*(Inputs!$B$35+Inputs!$B$36))<=0,"n/a",Model!$B$22/($B28*Inputs!$B$39+Inputs!$B$29+Inputs!$B$30-Inputs!$B$31-H$23-Inputs!$B$33-Inputs!$B$34-$B28*(Inputs!$B$35+Inputs!$B$36))) -> 866.61678
B29: Lower is better. 'n/a' means each extra order loses money, so no volume breaks even.

Sheet Scenarios
A1: Scenarios: four cases side by side
A2: Edit the blue changes (rows 5 to 10). Every change is my illustrative assumption, not a disclosed figure. Blinkit figures are for reference only.
A4: Changes vs base | B4: Base | C4: Density up | D4: Discount war | E4: Lever pack
A5: Change in AOV (₹) | B5: 0 | C5: 0 | D5: 0 | E5: 60
A6: Change in orders per store per day (%) | B6: 0 | C6: 0.3 | D6: 0.1 | E6: 0
A7: Change in delivery fee (₹) | B7: 0 | C7: 0 | D7: 0 | E7: 3
A8: Change in ad income per order (₹) | B8: 0 | C8: 0 | D8: 0 | E8: 5
A9: Change in discount per order (₹) | B9: 0 | C9: 0 | D9: 10 | E9: 0
A10: Change in rider cost per order (₹) | B10: 0 | C10: 0 | D10: 0 | E10: -3
A11: Density up = Blinkit-like store density (+30% orders). Discount war = ₹10 more discount for +10% orders. Lever pack = higher baskets, ad income and fees, slightly cheaper riders.
A12: Scenario inputs | B12: Base | C12: Density up | D12: Discount war | E12: Lever pack
A13: AOV (₹) | B13: =Inputs!$B$8+B5 -> 691 | C13: =Inputs!$B$8+C5 -> 691 | D13: =Inputs!$B$8+D5 -> 691 | E13: =Inputs!$B$8+E5 -> 751
A14: Orders per store per day | B14: =Inputs!$B$22*(1+B6) -> 1074.5019 | C14: =Inputs!$B$22*(1+C6) -> 1396.8525 | D14: =Inputs!$B$22*(1+D6) -> 1181.9521 | E14: =Inputs!$B$22*(1+E6) -> 1074.5019
A15: Delivery + handling fee (₹) | B15: =Inputs!$B$29+B7 -> 12 | C15: =Inputs!$B$29+C7 -> 12 | D15: =Inputs!$B$29+D7 -> 12 | E15: =Inputs!$B$29+E7 -> 15
A16: Ad income per order (₹) | B16: =Inputs!$B$30+B8 -> 10 | C16: =Inputs!$B$30+C8 -> 10 | D16: =Inputs!$B$30+D8 -> 10 | E16: =Inputs!$B$30+E8 -> 15
A17: Discount per order (₹) | B17: =Inputs!$B$31+B9 -> 6 | C17: =Inputs!$B$31+C9 -> 6 | D17: =Inputs!$B$31+D9 -> 16 | E17: =Inputs!$B$31+E9 -> 6
A18: Rider cost per order (₹) | B18: =Inputs!$B$32+B10 -> 45 | C18: =Inputs!$B$32+C10 -> 45 | D18: =Inputs!$B$32+D10 -> 45 | E18: =Inputs!$B$32+E10 -> 42
A19: Scenario outputs | B19: Base | C19: Density up | D19: Discount war | E19: Lever pack
A20: Revenue per order (₹) | B20: =B13*Inputs!$B$39+B15+B16-B17 -> 108 | C20: =C13*Inputs!$B$39+C15+C16-C17 -> 108 | D20: =D13*Inputs!$B$39+D15+D16-D17 -> 98 | E20: =E13*Inputs!$B$39+E15+E16-E17 -> 123.98842
A21: Variable cost per order (₹) | B21: =B18+Inputs!$B$33+Inputs!$B$34+B13*(Inputs!$B$35+Inputs!$B$36) -> 82.584 | C21: =C18+Inputs!$B$33+Inputs!$B$34+C13*(Inputs!$B$35+Inputs!$B$36) -> 82.584 | D21: =D18+Inputs!$B$33+Inputs!$B$34+D13*(Inputs!$B$35+Inputs!$B$36) -> 82.584 | E21: =E18+Inputs!$B$33+Inputs!$B$34+E13*(Inputs!$B$35+Inputs!$B$36) -> 81.024
A22: Unit contribution before fixed cost (₹) | B22: =B20-B21 -> 25.416 | C22: =C20-C21 -> 25.416 | D22: =D20-D21 -> 15.416 | E22: =E20-E21 -> 42.964423
A23: Fixed cost per store per day (₹) | B23: =Model!$B$22 -> 28794.503 | C23: =Model!$B$22 -> 28794.503 | D23: =Model!$B$22 -> 28794.503 | E23: =Model!$B$22 -> 28794.503
A24: Contribution per order after fixed cost (₹) | B24: =B22-B23/B14 -> -1.382 | C24: =C22-C23/C14 -> 4.8021538 | D24: =D22-D23/D14 -> -8.9458182 | E24: =E22-E23/E14 -> 16.166423
A25: Contribution margin (% of GOV) | B25: =B24/B13 -> -0.002 | C25: =C24/C13 -> 0.0069495714 | D25: =D24/D13 -> -0.012946191 | E25: =E24/E13 -> 0.021526528
A26: Contribution per store per month (₹) | B26: =B24*B14*Inputs!$B$48 -> -44548.85 | C26: =C24*C14*Inputs!$B$48 -> 201237.02 | D26: =D24*D14*Inputs!$B$48 -> -317205.86 | E26: =E24*E14*Inputs!$B$48 -> 521125.57
A27: All stores, per month (₹ crore) | B27: =B26*Inputs!$B$11/10000000 -> -5.2166703 | C27: =C26*Inputs!$B$11/10000000 -> 23.564855 | D27: =D26*Inputs!$B$11/10000000 -> -37.144807 | E27: =E26*Inputs!$B$11/10000000 -> 61.023804
A28: Break-even orders per store per day | B28: =IF(B22<=0,"n/a",B23/B22) -> 1132.9282 | C28: =IF(C22<=0,"n/a",C23/C22) -> 1132.9282 | D28: =IF(D22<=0,"n/a",D23/D22) -> 1867.8323 | E28: =IF(E22<=0,"n/a",E23/E22) -> 670.1941
A29: Change in contribution per store per month vs base (₹) | B29: =B26-$B$26 -> 0 | C29: =C26-$B$26 -> 245785.87 | D29: =D26-$B$26 -> -272657.01 | E29: =E26-$B$26 -> 565674.42
A31: Reference: Blinkit, Eternal Q1 FY27 (disclosed)
A32: Blinkit NAOV (₹) | B32: =Inputs!B16 -> 518
A33: Blinkit contribution (% of NOV) | B33: =Inputs!B18 -> 0.053
A34: Instamart base contribution (% of GOV) | B34: =B25 -> -0.002

Sheet Tornado
A1: Tornado: which input moves contribution most?
A2: Each input is moved down and up by the shock in B3, one at a time, everything else at base. Rows are ordered by swing as built; re-sort if you change inputs.
A3: Shock applied to each input | B3: 0.1
A5: Input | B5: Base value | C5: Down value | D5: Up value | E5: Contribution/store/month at down (₹) | F5: Contribution/store/month at up (₹) | G5: Change vs base, down (₹) | H5: Change vs base, up (₹) | I5: Swing (₹/store/month) | J5: Swing, all stores (₹ crore/month)
A6: AOV | B6: =Inputs!B8 -> 691 | C6: =B6*(1-$B$3) -> 621.9 | D6: =B6*(1+$B$3) -> 760.1 | E6: =Inputs!$B$48*((Inputs!$B$22)*(C6*Inputs!$B$39+Inputs!$B$29+Inputs!$B$30-Inputs!$B$31-Inputs!$B$32-Inputs!$B$33-Inputs!$B$34-C6*(Inputs!$B$35+Inputs!$B$36))-Model!$B$22) -> -287652.76 | F6: =Inputs!$B$48*((Inputs!$B$22)*(D6*Inputs!$B$39+Inputs!$B$29+Inputs!$B$30-Inputs!$B$31-Inputs!$B$32-Inputs!$B$33-Inputs!$B$34-D6*(Inputs!$B$35+Inputs!$B$36))-Model!$B$22) -> 198555.06 | G6: =E6-Model!$B$28 -> -243103.91 | H6: =F6-Model!$B$28 -> 243103.91 | I6: =ABS(F6-E6) -> 486207.82 | J6: =I6*Inputs!$B$11/10000000 -> 56.934936
A7: Rider cost per order | B7: =Inputs!B32 -> 45 | C7: =B7*(1-$B$3) -> 40.5 | D7: =B7*(1+$B$3) -> 49.5 | E7: =Inputs!$B$48*((Inputs!$B$22)*(Inputs!$B$8*Inputs!$B$39+Inputs!$B$29+Inputs!$B$30-Inputs!$B$31-C7-Inputs!$B$33-Inputs!$B$34-Inputs!$B$8*(Inputs!$B$35+Inputs!$B$36))-Model!$B$22) -> 100508.91 | F7: =Inputs!$B$48*((Inputs!$B$22)*(Inputs!$B$8*Inputs!$B$39+Inputs!$B$29+Inputs!$B$30-Inputs!$B$31-D7-Inputs!$B$33-Inputs!$B$34-Inputs!$B$8*(Inputs!$B$35+Inputs!$B$36))-Model!$B$22) -> -189606.61 | G7: =E7-Model!$B$28 -> 145057.76 | H7: =F7-Model!$B$28 -> -145057.76 | I7: =ABS(F7-E7) -> 290115.52 | J7: =I7*Inputs!$B$11/10000000 -> 33.972527
A8: Fixed cost per store per day | B8: =Model!B22 -> 28794.503 | C8: =B8*(1-$B$3) -> 25915.052 | D8: =B8*(1+$B$3) -> 31673.953 | E8: =Inputs!$B$48*((Inputs!$B$22)*(Inputs!$B$8*Inputs!$B$39+Inputs!$B$29+Inputs!$B$30-Inputs!$B$31-Inputs!$B$32-Inputs!$B$33-Inputs!$B$34-Inputs!$B$8*(Inputs!$B$35+Inputs!$B$36))-C8) -> 41834.658 | F8: =Inputs!$B$48*((Inputs!$B$22)*(Inputs!$B$8*Inputs!$B$39+Inputs!$B$29+Inputs!$B$30-Inputs!$B$31-Inputs!$B$32-Inputs!$B$33-Inputs!$B$34-Inputs!$B$8*(Inputs!$B$35+Inputs!$B$36))-D8) -> -130932.36 | G8: =E8-Model!$B$28 -> 86383.508 | H8: =F8-Model!$B$28 -> -86383.508 | I8: =ABS(F8-E8) -> 172767.02 | J8: =I8*Inputs!$B$11/10000000 -> 20.231018
A9: Orders per store per day | B9: =Inputs!B22 -> 1074.5019 | C9: =B9*(1-$B$3) -> 967.05174 | D9: =B9*(1+$B$3) -> 1181.9521 | E9: =Inputs!$B$48*(C9*(Inputs!$B$8*Inputs!$B$39+Inputs!$B$29+Inputs!$B$30-Inputs!$B$31-Inputs!$B$32-Inputs!$B$33-Inputs!$B$34-Inputs!$B$8*(Inputs!$B$35+Inputs!$B$36))-Model!$B$22) -> -126477.47 | F9: =Inputs!$B$48*(D9*(Inputs!$B$8*Inputs!$B$39+Inputs!$B$29+Inputs!$B$30-Inputs!$B$31-Inputs!$B$32-Inputs!$B$33-Inputs!$B$34-Inputs!$B$8*(Inputs!$B$35+Inputs!$B$36))-Model!$B$22) -> 37379.773 | G9: =E9-Model!$B$28 -> -81928.623 | H9: =F9-Model!$B$28 -> 81928.623 | I9: =ABS(F9-E9) -> 163857.25 | J9: =I9*Inputs!$B$11/10000000 -> 19.187684
A10: Picking and packing per order | B10: =Inputs!B33 -> 15 | C10: =B10*(1-$B$3) -> 13.5 | D10: =B10*(1+$B$3) -> 16.5 | E10: =Inputs!$B$48*((Inputs!$B$22)*(Inputs!$B$8*Inputs!$B$39+Inputs!$B$29+Inputs!$B$30-Inputs!$B$31-Inputs!$B$32-C10-Inputs!$B$34-Inputs!$B$8*(Inputs!$B$35+Inputs!$B$36))-Model!$B$22) -> 3803.7368 | F10: =Inputs!$B$48*((Inputs!$B$22)*(Inputs!$B$8*Inputs!$B$39+Inputs!$B$29+Inputs!$B$30-Inputs!$B$31-Inputs!$B$32-D10-Inputs!$B$34-Inputs!$B$8*(Inputs!$B$35+Inputs!$B$36))-Model!$B$22) -> -92901.437 | G10: =E10-Model!$B$28 -> 48352.587 | H10: =F10-Model!$B$28 -> -48352.587 | I10: =ABS(F10-E10) -> 96705.174 | J10: =I10*Inputs!$B$11/10000000 -> 11.324176
A11: Delivery + handling fee | B11: =Inputs!B29 -> 12 | C11: =B11*(1-$B$3) -> 10.8 | D11: =B11*(1+$B$3) -> 13.2 | E11: =Inputs!$B$48*((Inputs!$B$22)*(Inputs!$B$8*Inputs!$B$39+C11+Inputs!$B$30-Inputs!$B$31-Inputs!$B$32-Inputs!$B$33-Inputs!$B$34-Inputs!$B$8*(Inputs!$B$35+Inputs!$B$36))-Model!$B$22) -> -83230.919 | F11: =Inputs!$B$48*((Inputs!$B$22)*(Inputs!$B$8*Inputs!$B$39+D11+Inputs!$B$30-Inputs!$B$31-Inputs!$B$32-Inputs!$B$33-Inputs!$B$34-Inputs!$B$8*(Inputs!$B$35+Inputs!$B$36))-Model!$B$22) -> -5866.7805 | G11: =E11-Model!$B$28 -> -38682.069 | H11: =F11-Model!$B$28 -> 38682.069 | I11: =ABS(F11-E11) -> 77364.139 | J11: =I11*Inputs!$B$11/10000000 -> 9.0593407
A12: Ad income per order | B12: =Inputs!B30 -> 10 | C12: =B12*(1-$B$3) -> 9 | D12: =B12*(1+$B$3) -> 11 | E12: =Inputs!$B$48*((Inputs!$B$22)*(Inputs!$B$8*Inputs!$B$39+Inputs!$B$29+C12-Inputs!$B$31-Inputs!$B$32-Inputs!$B$33-Inputs!$B$34-Inputs!$B$8*(Inputs!$B$35+Inputs!$B$36))-Model!$B$22) -> -76783.908 | F12: =Inputs!$B$48*((Inputs!$B$22)*(Inputs!$B$8*Inputs!$B$39+Inputs!$B$29+D12-Inputs!$B$31-Inputs!$B$32-Inputs!$B$33-Inputs!$B$34-Inputs!$B$8*(Inputs!$B$35+Inputs!$B$36))-Model!$B$22) -> -12313.792 | G12: =E12-Model!$B$28 -> -32235.058 | H12: =F12-Model!$B$28 -> 32235.058 | I12: =ABS(F12-E12) -> 64470.116 | J12: =I12*Inputs!$B$11/10000000 -> 7.5494505
A13: Payment gateway % of AOV | B13: =Inputs!B35 -> 0.012 | C13: =B13*(1-$B$3) -> 0.0108 | D13: =B13*(1+$B$3) -> 0.0132 | E13: =Inputs!$B$48*((Inputs!$B$22)*(Inputs!$B$8*Inputs!$B$39+Inputs!$B$29+Inputs!$B$30-Inputs!$B$31-Inputs!$B$32-Inputs!$B$33-Inputs!$B$34-Inputs!$B$8*(C13+Inputs!$B$36))-Model!$B$22) -> -17819.54 | F13: =Inputs!$B$48*((Inputs!$B$22)*(Inputs!$B$8*Inputs!$B$39+Inputs!$B$29+Inputs!$B$30-Inputs!$B$31-Inputs!$B$32-Inputs!$B$33-Inputs!$B$34-Inputs!$B$8*(D13+Inputs!$B$36))-Model!$B$22) -> -71278.16 | G13: =E13-Model!$B$28 -> 26729.31 | H13: =F13-Model!$B$28 -> -26729.31 | I13: =ABS(F13-E13) -> 53458.62 | J13: =I13*Inputs!$B$11/10000000 -> 6.2600044
A14: Wastage % of AOV | B14: =Inputs!B36 -> 0.012 | C14: =B14*(1-$B$3) -> 0.0108 | D14: =B14*(1+$B$3) -> 0.0132 | E14: =Inputs!$B$48*((Inputs!$B$22)*(Inputs!$B$8*Inputs!$B$39+Inputs!$B$29+Inputs!$B$30-Inputs!$B$31-Inputs!$B$32-Inputs!$B$33-Inputs!$B$34-Inputs!$B$8*(Inputs!$B$35+C14))-Model!$B$22) -> -17819.54 | F14: =Inputs!$B$48*((Inputs!$B$22)*(Inputs!$B$8*Inputs!$B$39+Inputs!$B$29+Inputs!$B$30-Inputs!$B$31-Inputs!$B$32-Inputs!$B$33-Inputs!$B$34-Inputs!$B$8*(Inputs!$B$35+D14))-Model!$B$22) -> -71278.16 | G14: =E14-Model!$B$28 -> 26729.31 | H14: =F14-Model!$B$28 -> -26729.31 | I14: =ABS(F14-E14) -> 53458.62 | J14: =I14*Inputs!$B$11/10000000 -> 6.2600044
A15: Packaging per order | B15: =Inputs!B34 -> 6 | C15: =B15*(1-$B$3) -> 5.4 | D15: =B15*(1+$B$3) -> 6.6 | E15: =Inputs!$B$48*((Inputs!$B$22)*(Inputs!$B$8*Inputs!$B$39+Inputs!$B$29+Inputs!$B$30-Inputs!$B$31-Inputs!$B$32-Inputs!$B$33-C15-Inputs!$B$8*(Inputs!$B$35+Inputs!$B$36))-Model!$B$22) -> -25207.815 | F15: =Inputs!$B$48*((Inputs!$B$22)*(Inputs!$B$8*Inputs!$B$39+Inputs!$B$29+Inputs!$B$30-Inputs!$B$31-Inputs!$B$32-Inputs!$B$33-D15-Inputs!$B$8*(Inputs!$B$35+Inputs!$B$36))-Model!$B$22) -> -63889.885 | G15: =E15-Model!$B$28 -> 19341.035 | H15: =F15-Model!$B$28 -> -19341.035 | I15: =ABS(F15-E15) -> 38682.069 | J15: =I15*Inputs!$B$11/10000000 -> 4.5296703
A16: Discount per order | B16: =Inputs!B31 -> 6 | C16: =B16*(1-$B$3) -> 5.4 | D16: =B16*(1+$B$3) -> 6.6 | E16: =Inputs!$B$48*((Inputs!$B$22)*(Inputs!$B$8*Inputs!$B$39+Inputs!$B$29+Inputs!$B$30-C16-Inputs!$B$32-Inputs!$B$33-Inputs!$B$34-Inputs!$B$8*(Inputs!$B$35+Inputs!$B$36))-Model!$B$22) -> -25207.815 | F16: =Inputs!$B$48*((Inputs!$B$22)*(Inputs!$B$8*Inputs!$B$39+Inputs!$B$29+Inputs!$B$30-D16-Inputs!$B$32-Inputs!$B$33-Inputs!$B$34-Inputs!$B$8*(Inputs!$B$35+Inputs!$B$36))-Model!$B$22) -> -63889.885 | G16: =E16-Model!$B$28 -> 19341.035 | H16: =F16-Model!$B$28 -> -19341.035 | I16: =ABS(F16-E16) -> 38682.069 | J16: =I16*Inputs!$B$11/10000000 -> 4.5296703
A18: Base contribution per store per month (₹) | B18: =Model!B28 -> -44548.85
A19: Caution: each input moves alone. In reality AOV, volume and discounts move together (a higher discount lifts orders but cuts AOV).
A20: Fixed cost is per store per day. Product margin % is held constant, so an AOV change scales commission with it.

Sheet BreakEven
A1: Break-even chart: contribution per store per day vs orders per day
A2: The line crosses zero at the break-even volume (Model!B31).
A3: Orders per store per day | B3: Contribution per store per day (₹) | C3: Contribution per order (₹)
A4: 200 | B4: =A4*Model!$B$17-Model!$B$22 -> -23711.303 | C4: =B4/A4 -> -118.55651
A5: 400 | B5: =A5*Model!$B$17-Model!$B$22 -> -18628.103 | C5: =B5/A5 -> -46.570257
A6: 600 | B6: =A6*Model!$B$17-Model!$B$22 -> -13544.903 | C6: =B6/A6 -> -22.574838
A7: 800 | B7: =A7*Model!$B$17-Model!$B$22 -> -8461.7027 | C7: =B7/A7 -> -10.577128
A8: 1000 | B8: =A8*Model!$B$17-Model!$B$22 -> -3378.5027 | C8: =B8/A8 -> -3.3785027
A9: 1200 | B9: =A9*Model!$B$17-Model!$B$22 -> 1704.6973 | C9: =B9/A9 -> 1.4205811
A10: 1400 | B10: =A10*Model!$B$17-Model!$B$22 -> 6787.8973 | C10: =B10/A10 -> 4.8484981
A11: 1600 | B11: =A11*Model!$B$17-Model!$B$22 -> 11871.097 | C11: =B11/A11 -> 7.4194358
A12: 1800 | B12: =A12*Model!$B$17-Model!$B$22 -> 16954.297 | C12: =B12/A12 -> 9.4190541
A13: 2000 | B13: =A13*Model!$B$17-Model!$B$22 -> 22037.497 | C13: =B13/A13 -> 11.018749
A14: 2200 | B14: =A14*Model!$B$17-Model!$B$22 -> 27120.697 | C14: =B14/A14 -> 12.32759
A15: 2400 | B15: =A15*Model!$B$17-Model!$B$22 -> 32203.897 | C15: =B15/A15 -> 13.418291
... A17: 2800 | B17: =A17*Model!$B$17-Model!$B$22 -> 42370.297 | C17: =B17/A17 -> 15.132249

Sheet Checks
A1: Checks: does the model reproduce what the plan and Swiggy say?
A2: All rows should say PASS.
A3: Check | B3: Model | C3: Expected | D3: Result
A4: Orders per store per day is about 1,075 (plan) | B4: =Inputs!B22 -> 1074.5019 | C4: 1075 | D4: =IF(ABS(B4-C4)<1,"PASS","FAIL") -> PASS
A5: Take rate is 15.6% (plan) | B5: =ROUND(Inputs!B23,3) -> 0.156 | C5: 0.156 | D5: =IF(ABS(B5-C5)<0.0005,"PASS","FAIL") -> PASS
A6: Total cost per order is about ₹109 (plan) | B6: =ROUND(Inputs!B25,0) -> 109 | C6: 109 | D6: =IF(B6=C6,"PASS","FAIL") -> PASS
A7: Orders x AOV matches reported GOV (within 0.2%) | B7: =Inputs!B26 -> 7911.95 | C7: =Inputs!B6 -> 7907 | D7: =IF(ABS(B7/C7-1)<0.002,"PASS","FAIL") -> PASS
A8: Model revenue per order equals disclosed ₹108 | B8: =Model!B9 -> 108 | C8: =Inputs!B9 -> 108 | D8: =IF(ABS(B8-C8)<0.0001,"PASS","FAIL") -> PASS
A9: Model contribution margin equals disclosed -0.2% of GOV | B9: =Model!B26 -> -0.002 | C9: =Inputs!B10 -> -0.002 | D9: =IF(ABS(B9-C9)<0.000001,"PASS","FAIL") -> PASS
A10: Contribution is zero at the break-even volume | B10: =Model!B31*Model!B17-Model!B22 -> 0 | C10: 0 | D10: =IF(ABS(B10)<0.01,"PASS","FAIL") -> PASS
A11: Scenario base column equals the Model contribution | B11: =Scenarios!B26 -> -44548.85 | C11: =Model!B28 -> -44548.85 | D11: =IF(ABS(B11-C11)<0.01,"PASS","FAIL") -> PASS
A12: Sensitivity base cell (AOV and volume at base) equals disclosed -0.2% | B12: =Sensitivity!E8 -> -0.0019820317 | C12: =Inputs!B10 -> -0.002 | D12: =IF(ABS(B12-C12)<0.0005,"PASS","FAIL") -> PASS
A13: Tornado base equals Model contribution per store per month | B13: =Tornado!B18 -> -44548.85 | C13: =Model!B28 -> -44548.85 | D13: =IF(ABS(B13-C13)<0.01,"PASS","FAIL") -> PASS
A15: All checks pass? | D15: =IF(COUNTIF(D4:D13,"PASS")=10,"ALL PASS","REVIEW") -> ALL PASS
